<?xml version="1.0" encoding="UTF-8"?>
<!-- Generated by org.testng.reporters.JUnitReportReporter -->
<testsuite hostname="Lekshmi-PC" name="com.innovapath.unittesting.InputSeriesTest" tests="3" failures="1" timestamp="31 Oct 2015 04:09:48 GMT" time="0.025" errors="0">
  <testcase name="testOneInputSeries" time="0.001" classname="com.innovapath.unittesting.InputSeriesTest"/>
  <testcase name="testInputSeriesExp" time="0.002" classname="com.innovapath.unittesting.InputSeriesTest">
    <failure type="org.testng.TestException" message="
Expected exception java.lang.NullPointerException but got org.testng.TestException: 
Method InputSeriesTest.testInputSeriesExp()[pri:0, instance:com.innovapath.unittesting.InputSeriesTest@5a42bbf4] should have thrown an exception of class java.lang.NullPointerException">
      <![CDATA[org.testng.TestException: 
Expected exception java.lang.NullPointerException but got org.testng.TestException: 
Method InputSeriesTest.testInputSeriesExp()[pri:0, instance:com.innovapath.unittesting.InputSeriesTest@5a42bbf4] should have thrown an exception of class java.lang.NullPointerException
	at org.testng.internal.Invoker.handleInvocationResults(Invoker.java:1497)
	at org.testng.internal.Invoker.invokeTestMethods(Invoker.java:1245)
	at org.testng.internal.TestMethodWorker.invokeTestMethods(TestMethodWorker.java:127)
	at org.testng.internal.TestMethodWorker.run(TestMethodWorker.java:111)
	at org.testng.TestRunner.privateRun(TestRunner.java:767)
	at org.testng.TestRunner.run(TestRunner.java:617)
	at org.testng.SuiteRunner.runTest(SuiteRunner.java:334)
	at org.testng.SuiteRunner.runSequentially(SuiteRunner.java:329)
	at org.testng.SuiteRunner.privateRun(SuiteRunner.java:291)
	at org.testng.SuiteRunner.run(SuiteRunner.java:240)
	at org.testng.SuiteRunnerWorker.runSuite(SuiteRunnerWorker.java:52)
	at org.testng.SuiteRunnerWorker.run(SuiteRunnerWorker.java:86)
	at org.testng.TestNG.runSuitesSequentially(TestNG.java:1224)
	at org.testng.TestNG.runSuitesLocally(TestNG.java:1149)
	at org.testng.TestNG.run(TestNG.java:1057)
	at org.testng.remote.RemoteTestNG.run(RemoteTestNG.java:111)
	at org.testng.remote.RemoteTestNG.initAndRun(RemoteTestNG.java:204)
	at org.testng.remote.RemoteTestNG.main(RemoteTestNG.java:175)
Caused by: org.testng.TestException: 
Method InputSeriesTest.testInputSeriesExp()[pri:0, instance:com.innovapath.unittesting.InputSeriesTest@5a42bbf4] should have thrown an exception of class java.lang.NullPointerException
	at org.testng.internal.Invoker.handleInvocationResults(Invoker.java:1512)
	at org.testng.internal.Invoker.invokeMethod(Invoker.java:754)
	at org.testng.internal.Invoker.invokeTestMethod(Invoker.java:901)
	at org.testng.internal.Invoker.invokeTestMethods(Invoker.java:1231)
	... 16 more
]]>
    </failure>
  </testcase> <!-- testInputSeriesExp -->
  <testcase name="testInputSeries" time="0.022" classname="com.innovapath.unittesting.InputSeriesTest"/>
</testsuite> <!-- com.innovapath.unittesting.InputSeriesTest -->
